[32m2024-04-07 21:20:05 -0700[0m - dagster - [34mDEBUG[0m - reddit_job - abe27647-611e-423f-a92d-eff6a161b791 - 548584 - LOGS_CAPTURED - Started capturing logs in process (pid: 548584).
[32m2024-04-07 21:20:05 -0700[0m - dagster - [34mDEBUG[0m - reddit_job - abe27647-611e-423f-a92d-eff6a161b791 - 548584 - reddit_submissions - STEP_START - Started execution of step "reddit_submissions".
[32m2024-04-07 21:20:06 -0700[0m - dagster - [34mERROR[0m - [31mreddit_job - abe27647-611e-423f-a92d-eff6a161b791 - 548584 - reddit_submissions - STEP_FAILURE - Execution of step "reddit_submissions" failed.

dagster._core.errors.DagsterExecutionStepExecutionError: Error occurred while executing op "reddit_submissions"::

AttributeError: module 'pandas' has no attribute 'Dataframe'. Did you mean: 'DataFrame'?

Stack Trace:
  File "/home/anon/ubuntu-repos/third-times-the-charm/.venv/lib/python3.12/site-packages/dagster/_core/execution/plan/utils.py", line 54, in op_execution_error_boundary
    yield
  File "/home/anon/ubuntu-repos/third-times-the-charm/.venv/lib/python3.12/site-packages/dagster/_utils/__init__.py", line 463, in iterate_with_context
    next_output = next(iterator)
                  ^^^^^^^^^^^^^^
  File "/home/anon/ubuntu-repos/third-times-the-charm/.venv/lib/python3.12/site-packages/dagster/_core/execution/plan/compute_generator.py", line 131, in _coerce_op_compute_fn_to_iterator
    result = invoke_compute_fn(
             ^^^^^^^^^^^^^^^^^^
  File "/home/anon/ubuntu-repos/third-times-the-charm/.venv/lib/python3.12/site-packages/dagster/_core/execution/plan/compute_generator.py", line 125, in invoke_compute_fn
    return fn(context, **args_to_pass) if context_arg_provided else fn(**args_to_pass)
           ^^^^^^^^^^^^^^^^^^^^^^^^^^^
  File "/home/anon/ubuntu-repos/third-times-the-charm/anarchists-cookbook/anarchists_cookbook/assets/reddit_posts_comments_df.py", line 42, in reddit_submissions
    return pd.Dataframe(submissions_data)
           ^^^^^^^^^^^^
  File "/home/anon/ubuntu-repos/third-times-the-charm/.venv/lib/python3.12/site-packages/pandas/__init__.py", line 264, in __getattr__
    raise AttributeError(f"module 'pandas' has no attribute '{name}'")
[0m
